Workbook

Sheet DASHBOARD
A1: FINANZAS — DASHBOARD
G2: Last Sync | H2: 46079.219
A3: Inputs | D3: Metrics | G3: NAC File | H3: MovimientosNoFacturadosNacionales_26-02-2026.xls | date=20260226
A4: Salario (CLP) | B4: =CONFIG!B2 -> 3000000 | D4: Compras CC Nacional | E4: =RESUMEN!B2 -> 420514 | G4: INTL File | H4: MovimientosNoFacturadosInternacionales_26-02-2026.xls | date=20260226
A5: Housing (CLP) | B5: =CONFIG!B3 -> 1000000 | D5: Compras CC Intl (CLP) | E5: =RESUMEN!B3 -> 114218.5 | G5: Status | H5: SYNC OK | NAC:IMPORTED INTL:IMPORTED
A6: Familia (CLP) | B6: =CONFIG!B4 -> 300000 | D6: Pagos CC Nacional | E6: =RESUMEN!B4 -> 0 | G6: NAC Hash | H6: 1sVcdDjViWqprvwBy9u94CKQg166DXw5c|27601ba7fecf626a2eff5b0f4b2f57c1
A7: USD→CLP | B7: =CONFIG!B5 -> 950 | D7: Pagos CC Intl (CLP) | E7: =RESUMEN!B5 -> 0 | G7: INTL Hash | H7: 1Yuqq62vCosR0f9SFrcVpxI1fyVKM9D4i|7b5be5a3c8a826fd1bea52fa86e44635
A8: Claude plan (CLP) | B8: =CONFIG!B6 -> 0 | D8: Costos fijos | E8: =PROYECCION!B3 -> 1300000
D9: Margen disponible | E9: =PROYECCION!B7 -> 1165267.5
D10: FSI (margen/ingreso) | E10: =IFERROR(PROYECCION!B7/PROYECCION!B2,0) -> 0.3884225
A11: Stability Status
A12: Status | B12: =IF(E10<0.15,"🔴 RED",IF(E10<0.2,"🟡 YELLOW","🟢 GREEN")) -> 🟢 GREEN
A14: Auto-Savings Recommendation
A15: Recommended savings (CLP) | B15: =MAX(0,MIN(500000,PROYECCION!B7-300000)) -> 500000
A16: Buffer left after savings | B16: =PROYECCION!B7-B15 -> 665267.5
A18: Claude Upgrade Indicator
A19: Max 5x safe? | B19: =IF(PROYECCION!B7-100000>=300000,"YES","NO") -> YES
A20: Max 20x safe? | B20: =IF(PROYECCION!B7-200000>=300000,"YES","NO") -> YES
A22: Psychological Burn Threshold
A23: Threshold (CLP) | B23: =MAX(600000,PROYECCION!B2*0.25) -> 750000
A24: Day you cross threshold | B24: =IFERROR(ROUNDUP(B23/(PROYECCION!B7/30),0),"") -> 20
A26: Actions
A27: Rule | B27: Pay housing + family first. Auto-save B15 on day 1. Then spend normally.

Sheet PREVIEW_SUMMARY
A1: PREVIEW IMPORT SUMMARY
A2: Generated at | B2: 46079.219
A4: NAC file | B4: MovimientosNoFacturadosNacionales_26-02-2026.xls
A5: NAC parsed date | B5: 20260226
A6: NAC checksum (MD5) | B6: 1sVcdDjViWqprvwBy9u94CKQg166DXw5c|27601ba7fecf626a2eff5b0f4b2f57c1
A7: NAC rows (ex header) | B7: 20
A8: NAC total (preview) | B8: 420514
A9: NAC total (current live) | B9: -269753
A10: NAC delta (preview - live) | B10: 690267
A12: INTL file | B12: MovimientosNoFacturadosInternacionales_26-02-2026.xls
A13: INTL parsed date | B13: 20260226
A14: INTL checksum (MD5) | B14: 1Yuqq62vCosR0f9SFrcVpxI1fyVKM9D4i|7b5be5a3c8a826fd1bea52fa86e44635
A15: INTL rows (ex header) | B15: 3
A16: INTL total (preview) | B16: 120.23
A17: INTL total (current live) | B17: -36.69
A18: INTL delta (preview - live) | B18: 156.92
A20: Next step | B20: Use Finanzas menu or buttons: Preview / Confirm / Cancel.

Sheet PREVIEW_NAC
A1: Fecha | B1: Descripcion | C1: Monto_CLP
A2: 25-02-2026 | B2: UBER RIDES UBER RIDES LAS CO | C2: 12931
A3: 25-02-2026 | B3: CHILE DOGS LTDA CON CO | C3: 46990
A4: 24-02-2026 | B4: PAYU *FLIXBUS SANTIA | C4: 6499
A5: 24-02-2026 | B5: PAYU *UBER TRIP SANTIA | C5: 12600
A6: 24-02-2026 | B6: PAYU *FLIXBUS SANTIA | C6: 4999
A7: 24-02-2026 | B7: PAYU *UBER TRIP SANTIA | C7: 6078
A8: 23-02-2026 | B8: MERCADOPAGO*MERCADO COMPRAS | C8: 11980
A9: 23-02-2026 | B9: PAYU *FLIXBUS COMPRAS | C9: 7699
A10: 21-02-2026 | B10: LOCAL EU 15 NORTE COMPRAS | C10: 19990
A11: 21-02-2026 | B11: MORA LOUTIT SWEET S COMPRAS | C11: 11550
A12: 23-02-2026 | B12: MERCADOPAGO*MERCADO 03 CTAS-INT: 0 | C12: 86791
A13: 21-02-2026 | B13: MERPAGO*OPTICASLUXO HUE CC 01-06 | C13: 41030
... A16: 21-01-2026 | B16: MP *MERCADO LIB SAN CC 02-03 | C16: 15295
A17: 46235 | B17: MP *MERCADO LIB SAN CC 03-06 | C17: 20813
A18: 46204 | B18: MERCADOPAGO*STREETD LAS CF 02-06 | C18: 10997
A19: 21-12-2025 | B19: MERPAGO*MERCADOLIBR LAS CC 03-03 | C19: 17538
A20: 28-11-2025 | B20: CIC HOGAR TIENDA CO CON CC 04-06 | C20: 20496
A21: 28-08-2025 | B21: MERCADOPAGO*MONSTER LAS CF 06-06 | C21: 14667

Sheet PREVIEW_INTL
A1: Fecha | B1: Descripcion | C1: Monto_USD
A2: 22-02-2026 | B2: EMBY PREMIERE COMPRAS INT.VI | C2: 4.99
A3: 20-02-2026 | B3: CLAUDE.AI SUBSCRIPT COMPRAS INT.VI | C3: 102.76
A4: 19-02-2026 | B4: APPLE.COM/BILL COMPRAS INT.VI | C4: 12.48

Sheet CONFIG
A1: Parametro | B1: Valor | D1: NOTE
A2: SALARIO | B2: 3000000 | D2: In Google Sheets, set HOUSING to IMPORTRANGE from your other sheet (Gordo!O1) using the sanitize formula.
A3: HOUSING | B3: 1000000
A4: FAMILIA | B4: 300000
A5: USD_CLP | B5: 950
A6: CLAUDE_PLAN | B6: 0

Sheet CUOTAS
A1: Fuente | B1: Fecha | C1: Descripcion | D1: Monto | E1: Moneda | F1: Es_cuotas | G1: Cuota_actual | H1: Cuotas_totales | I1: Cuotas_restantes | J1: Monto_restante_estimado | L1: RESUMEN
A2: NAC | B2: =IF(MOV_CC_NACIONAL!A2="","",MOV_CC_NACIONAL!A2) -> 25-02-2026 | C2: =IF(MOV_CC_NACIONAL!B2="","",MOV_CC_NACIONAL!B2) -> UBER RIDES UBER RIDES LAS CO | D2: =IF(MOV_CC_NACIONAL!C2="","",MOV_CC_NACIONAL!C2) -> 12931 | E2: =IF(B2="","", "CLP") -> CLP | F2: =IFERROR(__xludf.DUMMYFUNCTION("IF(C2="""","""", OR(REGEXMATCH(LOWER(C2),""cuota""), REGEXMATCH(C2,""\d+\s*/\s*\d+"")))"),FALSE) -> FALSE | G2: =IFERROR(__xludf.DUMMYFUNCTION("IFERROR(VALUE(REGEXEXTRACT(C2,""(\d+)\s*/\s*\d+"")),"""")"),"") | H2: =IFERROR(__xludf.DUMMYFUNCTION("IFERROR(VALUE(REGEXEXTRACT(C2,""\d+\s*/\s*(\d+)"")),"""")"),"") | I2: =IF(OR(G2="",H2=""),"",H2-G2) | J2: =IF(OR(D2="",I2=""),"",D2*I2) | L2: Total restante (est.) | M2: =SUMIF(F:F,TRUE,J:J) -> 0
A3: NAC | B3: =IF(MOV_CC_NACIONAL!A3="","",MOV_CC_NACIONAL!A3) -> 25-02-2026 | C3: =IF(MOV_CC_NACIONAL!B3="","",MOV_CC_NACIONAL!B3) -> CHILE DOGS LTDA CON CO | D3: =IF(MOV_CC_NACIONAL!C3="","",MOV_CC_NACIONAL!C3) -> 46990 | E3: =IF(B3="","", "CLP") -> CLP | F3: =IFERROR(__xludf.DUMMYFUNCTION("IF(C3="""","""", OR(REGEXMATCH(LOWER(C3),""cuota""), REGEXMATCH(C3,""\d+\s*/\s*\d+"")))"),FALSE) -> FALSE | G3: =IFERROR(__xludf.DUMMYFUNCTION("IFERROR(VALUE(REGEXEXTRACT(C3,""(\d+)\s*/\s*\d+"")),"""")"),"") | H3: =IFERROR(__xludf.DUMMYFUNCTION("IFERROR(VALUE(REGEXEXTRACT(C3,""\d+\s*/\s*(\d+)"")),"""")"),"") | I3: =IF(OR(G3="",H3=""),"",H3-G3) | J3: =IF(OR(D3="",I3=""),"",D3*I3) | L3: Cuotas activas (count) | M3: =COUNTIF(F:F,TRUE) -> 0
A4: NAC | B4: =IF(MOV_CC_NACIONAL!A4="","",MOV_CC_NACIONAL!A4) -> 24-02-2026 | C4: =IF(MOV_CC_NACIONAL!B4="","",MOV_CC_NACIONAL!B4) -> PAYU *FLIXBUS SANTIA | D4: =IF(MOV_CC_NACIONAL!C4="","",MOV_CC_NACIONAL!C4) -> 6499 | E4: =IF(B4="","", "CLP") -> CLP | F4: =IFERROR(__xludf.DUMMYFUNCTION("IF(C4="""","""", OR(REGEXMATCH(LOWER(C4),""cuota""), REGEXMATCH(C4,""\d+\s*/\s*\d+"")))"),FALSE) -> FALSE | G4: =IFERROR(__xludf.DUMMYFUNCTION("IFERROR(VALUE(REGEXEXTRACT(C4,""(\d+)\s*/\s*\d+"")),"""")"),"") | H4: =IFERROR(__xludf.DUMMYFUNCTION("IFERROR(VALUE(REGEXEXTRACT(C4,""\d+\s*/\s*(\d+)"")),"""")"),"") | I4: =IF(OR(G4="",H4=""),"",H4-G4) | J4: =IF(OR(D4="",I4=""),"",D4*I4)
A5: NAC | B5: =IF(MOV_CC_NACIONAL!A5="","",MOV_CC_NACIONAL!A5) -> 24-02-2026 | C5: =IF(MOV_CC_NACIONAL!B5="","",MOV_CC_NACIONAL!B5) -> PAYU *UBER TRIP SANTIA | D5: =IF(MOV_CC_NACIONAL!C5="","",MOV_CC_NACIONAL!C5) -> 12600 | E5: =IF(B5="","", "CLP") -> CLP | F5: =IFERROR(__xludf.DUMMYFUNCTION("IF(C5="""","""", OR(REGEXMATCH(LOWER(C5),""cuota""), REGEXMATCH(C5,""\d+\s*/\s*\d+"")))"),FALSE) -> FALSE | G5: =IFERROR(__xludf.DUMMYFUNCTION("IFERROR(VALUE(REGEXEXTRACT(C5,""(\d+)\s*/\s*\d+"")),"""")"),"") | H5: =IFERROR(__xludf.DUMMYFUNCTION("IFERROR(VALUE(REGEXEXTRACT(C5,""\d+\s*/\s*(\d+)"")),"""")"),"") | I5: =IF(OR(G5="",H5=""),"",H5-G5) | J5: =IF(OR(D5="",I5=""),"",D5*I5) | L5: Nota: | M5: Estas fórmulas usan REGEX* (funciones de Google Sheets). Al abrir en Google Sheets funcionará.
A6: NAC | B6: =IF(MOV_CC_NACIONAL!A6="","",MOV_CC_NACIONAL!A6) -> 24-02-2026 | C6: =IF(MOV_CC_NACIONAL!B6="","",MOV_CC_NACIONAL!B6) -> PAYU *FLIXBUS SANTIA | D6: =IF(MOV_CC_NACIONAL!C6="","",MOV_CC_NACIONAL!C6) -> 4999 | E6: =IF(B6="","", "CLP") -> CLP | F6: =IFERROR(__xludf.DUMMYFUNCTION("IF(C6="""","""", OR(REGEXMATCH(LOWER(C6),""cuota""), REGEXMATCH(C6,""\d+\s*/\s*\d+"")))"),FALSE) -> FALSE | G6: =IFERROR(__xludf.DUMMYFUNCTION("IFERROR(VALUE(REGEXEXTRACT(C6,""(\d+)\s*/\s*\d+"")),"""")"),"") | H6: =IFERROR(__xludf.DUMMYFUNCTION("IFERROR(VALUE(REGEXEXTRACT(C6,""\d+\s*/\s*(\d+)"")),"""")"),"") | I6: =IF(OR(G6="",H6=""),"",H6-G6) | J6: =IF(OR(D6="",I6=""),"",D6*I6)
A7: NAC | B7: =IF(MOV_CC_NACIONAL!A7="","",MOV_CC_NACIONAL!A7) -> 24-02-2026 | C7: =IF(MOV_CC_NACIONAL!B7="","",MOV_CC_NACIONAL!B7) -> PAYU *UBER TRIP SANTIA | D7: =IF(MOV_CC_NACIONAL!C7="","",MOV_CC_NACIONAL!C7) -> 6078 | E7: =IF(B7="","", "CLP") -> CLP | F7: =IFERROR(__xludf.DUMMYFUNCTION("IF(C7="""","""", OR(REGEXMATCH(LOWER(C7),""cuota""), REGEXMATCH(C7,""\d+\s*/\s*\d+"")))"),FALSE) -> FALSE | G7: =IFERROR(__xludf.DUMMYFUNCTION("IFERROR(VALUE(REGEXEXTRACT(C7,""(\d+)\s*/\s*\d+"")),"""")"),"") | H7: =IFERROR(__xludf.DUMMYFUNCTION("IFERROR(VALUE(REGEXEXTRACT(C7,""\d+\s*/\s*(\d+)"")),"""")"),"") | I7: =IF(OR(G7="",H7=""),"",H7-G7) | J7: =IF(OR(D7="",I7=""),"",D7*I7) | L7: Vista (solo cuotas)
A8: NAC | B8: =IF(MOV_CC_NACIONAL!A8="","",MOV_CC_NACIONAL!A8) -> 23-02-2026 | C8: =IF(MOV_CC_NACIONAL!B8="","",MOV_CC_NACIONAL!B8) -> MERCADOPAGO*MERCADO COMPRAS | D8: =IF(MOV_CC_NACIONAL!C8="","",MOV_CC_NACIONAL!C8) -> 11980 | E8: =IF(B8="","", "CLP") -> CLP | F8: =IFERROR(__xludf.DUMMYFUNCTION("IF(C8="""","""", OR(REGEXMATCH(LOWER(C8),""cuota""), REGEXMATCH(C8,""\d+\s*/\s*\d+"")))"),FALSE) -> FALSE | G8: =IFERROR(__xludf.DUMMYFUNCTION("IFERROR(VALUE(REGEXEXTRACT(C8,""(\d+)\s*/\s*\d+"")),"""")"),"") | H8: =IFERROR(__xludf.DUMMYFUNCTION("IFERROR(VALUE(REGEXEXTRACT(C8,""\d+\s*/\s*(\d+)"")),"""")"),"") | I8: =IF(OR(G8="",H8=""),"",H8-G8) | J8: =IF(OR(D8="",I8=""),"",D8*I8) | L8: =IFERROR(__xludf.DUMMYFUNCTION("QUERY(A1:J,""select A,B,C,D,E,G,H,I,J where F = TRUE"",1)"),"#NAME?") -> #NAME?
A9: NAC | B9: =IF(MOV_CC_NACIONAL!A9="","",MOV_CC_NACIONAL!A9) -> 23-02-2026 | C9: =IF(MOV_CC_NACIONAL!B9="","",MOV_CC_NACIONAL!B9) -> PAYU *FLIXBUS COMPRAS | D9: =IF(MOV_CC_NACIONAL!C9="","",MOV_CC_NACIONAL!C9) -> 7699 | E9: =IF(B9="","", "CLP") -> CLP | F9: =IFERROR(__xludf.DUMMYFUNCTION("IF(C9="""","""", OR(REGEXMATCH(LOWER(C9),""cuota""), REGEXMATCH(C9,""\d+\s*/\s*\d+"")))"),FALSE) -> FALSE | G9: =IFERROR(__xludf.DUMMYFUNCTION("IFERROR(VALUE(REGEXEXTRACT(C9,""(\d+)\s*/\s*\d+"")),"""")"),"") | H9: =IFERROR(__xludf.DUMMYFUNCTION("IFERROR(VALUE(REGEXEXTRACT(C9,""\d+\s*/\s*(\d+)"")),"""")"),"") | I9: =IF(OR(G9="",H9=""),"",H9-G9) | J9: =IF(OR(D9="",I9=""),"",D9*I9)
A10: NAC | B10: =IF(MOV_CC_NACIONAL!A10="","",MOV_CC_NACIONAL!A10) -> 21-02-2026 | C10: =IF(MOV_CC_NACIONAL!B10="","",MOV_CC_NACIONAL!B10) -> LOCAL EU 15 NORTE COMPRAS | D10: =IF(MOV_CC_NACIONAL!C10="","",MOV_CC_NACIONAL!C10) -> 19990 | E10: =IF(B10="","", "CLP") -> CLP | F10: =IFERROR(__xludf.DUMMYFUNCTION("IF(C10="""","""", OR(REGEXMATCH(LOWER(C10),""cuota""), REGEXMATCH(C10,""\d+\s*/\s*\d+"")))"),FALSE) -> FALSE | G10: =IFERROR(__xludf.DUMMYFUNCTION("IFERROR(VALUE(REGEXEXTRACT(C10,""(\d+)\s*/\s*\d+"")),"""")"),"") | H10: =IFERROR(__xludf.DUMMYFUNCTION("IFERROR(VALUE(REGEXEXTRACT(C10,""\d+\s*/\s*(\d+)"")),"""")"),"") | I10: =IF(OR(G10="",H10=""),"",H10-G10) | J10: =IF(OR(D10="",I10=""),"",D10*I10)
A11: NAC | B11: =IF(MOV_CC_NACIONAL!A11="","",MOV_CC_NACIONAL!A11) -> 21-02-2026 | C11: =IF(MOV_CC_NACIONAL!B11="","",MOV_CC_NACIONAL!B11) -> MORA LOUTIT SWEET S COMPRAS | D11: =IF(MOV_CC_NACIONAL!C11="","",MOV_CC_NACIONAL!C11) -> 11550 | E11: =IF(B11="","", "CLP") -> CLP | F11: =IFERROR(__xludf.DUMMYFUNCTION("IF(C11="""","""", OR(REGEXMATCH(LOWER(C11),""cuota""), REGEXMATCH(C11,""\d+\s*/\s*\d+"")))"),FALSE) -> FALSE | G11: =IFERROR(__xludf.DUMMYFUNCTION("IFERROR(VALUE(REGEXEXTRACT(C11,""(\d+)\s*/\s*\d+"")),"""")"),"") | H11: =IFERROR(__xludf.DUMMYFUNCTION("IFERROR(VALUE(REGEXEXTRACT(C11,""\d+\s*/\s*(\d+)"")),"""")"),"") | I11: =IF(OR(G11="",H11=""),"",H11-G11) | J11: =IF(OR(D11="",I11=""),"",D11*I11)
A12: NAC | B12: =IF(MOV_CC_NACIONAL!A12="","",MOV_CC_NACIONAL!A12) -> 23-02-2026 | C12: =IF(MOV_CC_NACIONAL!B12="","",MOV_CC_NACIONAL!B12) -> MERCADOPAGO*MERCADO 03 CTAS-INT: 0 | D12: =IF(MOV_CC_NACIONAL!C12="","",MOV_CC_NACIONAL!C12) -> 86791 | E12: =IF(B12="","", "CLP") -> CLP | F12: =IFERROR(__xludf.DUMMYFUNCTION("IF(C12="""","""", OR(REGEXMATCH(LOWER(C12),""cuota""), REGEXMATCH(C12,""\d+\s*/\s*\d+"")))"),FALSE) -> FALSE | G12: =IFERROR(__xludf.DUMMYFUNCTION("IFERROR(VALUE(REGEXEXTRACT(C12,""(\d+)\s*/\s*\d+"")),"""")"),"") | H12: =IFERROR(__xludf.DUMMYFUNCTION("IFERROR(VALUE(REGEXEXTRACT(C12,""\d+\s*/\s*(\d+)"")),"""")"),"") | I12: =IF(OR(G12="",H12=""),"",H12-G12) | J12: =IF(OR(D12="",I12=""),"",D12*I12)
A13: NAC | B13: =IF(MOV_CC_NACIONAL!A13="","",MOV_CC_NACIONAL!A13) -> 21-02-2026 | C13: =IF(MOV_CC_NACIONAL!B13="","",MOV_CC_NACIONAL!B13) -> MERPAGO*OPTICASLUXO HUE CC 01-06 | D13: =IF(MOV_CC_NACIONAL!C13="","",MOV_CC_NACIONAL!C13) -> 41030 | E13: =IF(B13="","", "CLP") -> CLP | F13: =IFERROR(__xludf.DUMMYFUNCTION("IF(C13="""","""", OR(REGEXMATCH(LOWER(C13),""cuota""), REGEXMATCH(C13,""\d+\s*/\s*\d+"")))"),FALSE) -> FALSE | G13: =IFERROR(__xludf.DUMMYFUNCTION("IFERROR(VALUE(REGEXEXTRACT(C13,""(\d+)\s*/\s*\d+"")),"""")"),"") | H13: =IFERROR(__xludf.DUMMYFUNCTION("IFERROR(VALUE(REGEXEXTRACT(C13,""\d+\s*/\s*(\d+)"")),"""")"),"") | I13: =IF(OR(G13="",H13=""),"",H13-G13) | J13: =IF(OR(D13="",I13=""),"",D13*I13)
A14: NAC | B14: =IF(MOV_CC_NACIONAL!A14="","",MOV_CC_NACIONAL!A14) -> 21-02-2026 | C14: =IF(MOV_CC_NACIONAL!B14="","",MOV_CC_NACIONAL!B14) -> MERPAGO*OPTICASLUXO HUE CC 01-06 | D14: =IF(MOV_CC_NACIONAL!C14="","",MOV_CC_NACIONAL!C14) -> 18331 | E14: =IF(B14="","", "CLP") -> CLP | F14: =IFERROR(__xludf.DUMMYFUNCTION("IF(C14="""","""", OR(REGEXMATCH(LOWER(C14),""cuota""), REGEXMATCH(C14,""\d+\s*/\s*\d+"")))"),FALSE) -> FALSE | G14: =IFERROR(__xludf.DUMMYFUNCTION("IFERROR(VALUE(REGEXEXTRACT(C14,""(\d+)\s*/\s*\d+"")),"""")"),"") | H14: =IFERROR(__xludf.DUMMYFUNCTION("IFERROR(VALUE(REGEXEXTRACT(C14,""\d+\s*/\s*(\d+)"")),"""")"),"") | I14: =IF(OR(G14="",H14=""),"",H14-G14) | J14: =IF(OR(D14="",I14=""),"",D14*I14)
A15: NAC | B15: =IF(MOV_CC_NACIONAL!A15="","",MOV_CC_NACIONAL!A15) -> 14-02-2026 | C15: =IF(MOV_CC_NACIONAL!B15="","",MOV_CC_NACIONAL!B15) -> DP *IKEA COM SAN CF 01-03 | D15: =IF(MOV_CC_NACIONAL!C15="","",MOV_CC_NACIONAL!C15) -> 33240 | E15: =IF(B15="","", "CLP") -> CLP | F15: =IFERROR(__xludf.DUMMYFUNCTION("IF(C15="""","""", OR(REGEXMATCH(LOWER(C15),""cuota""), REGEXMATCH(C15,""\d+\s*/\s*\d+"")))"),FALSE) -> FALSE | G15: =IFERROR(__xludf.DUMMYFUNCTION("IFERROR(VALUE(REGEXEXTRACT(C15,""(\d+)\s*/\s*\d+"")),"""")"),"") | H15: =IFERROR(__xludf.DUMMYFUNCTION("IFERROR(VALUE(REGEXEXTRACT(C15,""\d+\s*/\s*(\d+)"")),"""")"),"") | I15: =IF(OR(G15="",H15=""),"",H15-G15) | J15: =IF(OR(D15="",I15=""),"",D15*I15)
A16: NAC | B16: =IF(MOV_CC_NACIONAL!A16="","",MOV_CC_NACIONAL!A16) -> 21-01-2026 | C16: =IF(MOV_CC_NACIONAL!B16="","",MOV_CC_NACIONAL!B16) -> MP *MERCADO LIB SAN CC 02-03 | D16: =IF(MOV_CC_NACIONAL!C16="","",MOV_CC_NACIONAL!C16) -> 15295 | E16: =IF(B16="","", "CLP") -> CLP | F16: =IFERROR(__xludf.DUMMYFUNCTION("IF(C16="""","""", OR(REGEXMATCH(LOWER(C16),""cuota""), REGEXMATCH(C16,""\d+\s*/\s*\d+"")))"),FALSE) -> FALSE | G16: =IFERROR(__xludf.DUMMYFUNCTION("IFERROR(VALUE(REGEXEXTRACT(C16,""(\d+)\s*/\s*\d+"")),"""")"),"") | H16: =IFERROR(__xludf.DUMMYFUNCTION("IFERROR(VALUE(REGEXEXTRACT(C16,""\d+\s*/\s*(\d+)"")),"""")"),"") | I16: =IF(OR(G16="",H16=""),"",H16-G16) | J16: =IF(OR(D16="",I16=""),"",D16*I16)
A17: NAC | B17: =IF(MOV_CC_NACIONAL!A17="","",MOV_CC_NACIONAL!A17) -> 46235 | C17: =IF(MOV_CC_NACIONAL!B17="","",MOV_CC_NACIONAL!B17) -> MP *MERCADO LIB SAN CC 03-06 | D17: =IF(MOV_CC_NACIONAL!C17="","",MOV_CC_NACIONAL!C17) -> 20813 | E17: =IF(B17="","", "CLP") -> CLP | F17: =IFERROR(__xludf.DUMMYFUNCTION("IF(C17="""","""", OR(REGEXMATCH(LOWER(C17),""cuota""), REGEXMATCH(C17,""\d+\s*/\s*\d+"")))"),FALSE) -> FALSE | G17: =IFERROR(__xludf.DUMMYFUNCTION("IFERROR(VALUE(REGEXEXTRACT(C17,""(\d+)\s*/\s*\d+"")),"""")"),"") | H17: =IFERROR(__xludf.DUMMYFUNCTION("IFERROR(VALUE(REGEXEXTRACT(C17,""\d+\s*/\s*(\d+)"")),"""")"),"") | I17: =IF(OR(G17="",H17=""),"",H17-G17) | J17: =IF(OR(D17="",I17=""),"",D17*I17)
A18: NAC | B18: =IF(MOV_CC_NACIONAL!A18="","",MOV_CC_NACIONAL!A18) -> 46204 | C18: =IF(MOV_CC_NACIONAL!B18="","",MOV_CC_NACIONAL!B18) -> MERCADOPAGO*STREETD LAS CF 02-06 | D18: =IF(MOV_CC_NACIONAL!C18="","",MOV_CC_NACIONAL!C18) -> 10997 | E18: =IF(B18="","", "CLP") -> CLP | F18: =IFERROR(__xludf.DUMMYFUNCTION("IF(C18="""","""", OR(REGEXMATCH(LOWER(C18),""cuota""), REGEXMATCH(C18,""\d+\s*/\s*\d+"")))"),FALSE) -> FALSE | G18: =IFERROR(__xludf.DUMMYFUNCTION("IFERROR(VALUE(REGEXEXTRACT(C18,""(\d+)\s*/\s*\d+"")),"""")"),"") | H18: =IFERROR(__xludf.DUMMYFUNCTION("IFERROR(VALUE(REGEXEXTRACT(C18,""\d+\s*/\s*(\d+)"")),"""")"),"") | I18: =IF(OR(G18="",H18=""),"",H18-G18) | J18: =IF(OR(D18="",I18=""),"",D18*I18)
A19: NAC | B19: =IF(MOV_CC_NACIONAL!A19="","",MOV_CC_NACIONAL!A19) -> 21-12-2025 | C19: =IF(MOV_CC_NACIONAL!B19="","",MOV_CC_NACIONAL!B19) -> MERPAGO*MERCADOLIBR LAS CC 03-03 | D19: =IF(MOV_CC_NACIONAL!C19="","",MOV_CC_NACIONAL!C19) -> 17538 | E19: =IF(B19="","", "CLP") -> CLP | F19: =IFERROR(__xludf.DUMMYFUNCTION("IF(C19="""","""", OR(REGEXMATCH(LOWER(C19),""cuota""), REGEXMATCH(C19,""\d+\s*/\s*\d+"")))"),FALSE) -> FALSE | G19: =IFERROR(__xludf.DUMMYFUNCTION("IFERROR(VALUE(REGEXEXTRACT(C19,""(\d+)\s*/\s*\d+"")),"""")"),"") | H19: =IFERROR(__xludf.DUMMYFUNCTION("IFERROR(VALUE(REGEXEXTRACT(C19,""\d+\s*/\s*(\d+)"")),"""")"),"") | I19: =IF(OR(G19="",H19=""),"",H19-G19) | J19: =IF(OR(D19="",I19=""),"",D19*I19)
A20: NAC | B20: =IF(MOV_CC_NACIONAL!A20="","",MOV_CC_NACIONAL!A20) -> 28-11-2025 | C20: =IF(MOV_CC_NACIONAL!B20="","",MOV_CC_NACIONAL!B20) -> CIC HOGAR TIENDA CO CON CC 04-06 | D20: =IF(MOV_CC_NACIONAL!C20="","",MOV_CC_NACIONAL!C20) -> 20496 | E20: =IF(B20="","", "CLP") -> CLP | F20: =IFERROR(__xludf.DUMMYFUNCTION("IF(C20="""","""", OR(REGEXMATCH(LOWER(C20),""cuota""), REGEXMATCH(C20,""\d+\s*/\s*\d+"")))"),FALSE) -> FALSE | G20: =IFERROR(__xludf.DUMMYFUNCTION("IFERROR(VALUE(REGEXEXTRACT(C20,""(\d+)\s*/\s*\d+"")),"""")"),"") | H20: =IFERROR(__xludf.DUMMYFUNCTION("IFERROR(VALUE(REGEXEXTRACT(C20,""\d+\s*/\s*(\d+)"")),"""")"),"") | I20: =IF(OR(G20="",H20=""),"",H20-G20) | J20: =IF(OR(D20="",I20=""),"",D20*I20)
A21: NAC | B21: =IF(MOV_CC_NACIONAL!A21="","",MOV_CC_NACIONAL!A21) -> 28-08-2025 | C21: =IF(MOV_CC_NACIONAL!B21="","",MOV_CC_NACIONAL!B21) -> MERCADOPAGO*MONSTER LAS CF 06-06 | D21: =IF(MOV_CC_NACIONAL!C21="","",MOV_CC_NACIONAL!C21) -> 14667 | E21: =IF(B21="","", "CLP") -> CLP | F21: =IFERROR(__xludf.DUMMYFUNCTION("IF(C21="""","""", OR(REGEXMATCH(LOWER(C21),""cuota""), REGEXMATCH(C21,""\d+\s*/\s*\d+"")))"),FALSE) -> FALSE | G21: =IFERROR(__xludf.DUMMYFUNCTION("IFERROR(VALUE(REGEXEXTRACT(C21,""(\d+)\s*/\s*\d+"")),"""")"),"") | H21: =IFERROR(__xludf.DUMMYFUNCTION("IFERROR(VALUE(REGEXEXTRACT(C21,""\d+\s*/\s*(\d+)"")),"""")"),"") | I21: =IF(OR(G21="",H21=""),"",H21-G21) | J21: =IF(OR(D21="",I21=""),"",D21*I21)
A22: NAC | B22: =IF(MOV_CC_NACIONAL!A22="","",MOV_CC_NACIONAL!A22) | C22: =IF(MOV_CC_NACIONAL!B22="","",MOV_CC_NACIONAL!B22) | D22: =IF(MOV_CC_NACIONAL!C22="","",MOV_CC_NACIONAL!C22) | E22: =IF(B22="","", "CLP") | F22: =IFERROR(__xludf.DUMMYFUNCTION("IF(C22="""","""", OR(REGEXMATCH(LOWER(C22),""cuota""), REGEXMATCH(C22,""\d+\s*/\s*\d+"")))"),"") | G22: =IFERROR(__xludf.DUMMYFUNCTION("IFERROR(VALUE(REGEXEXTRACT(C22,""(\d+)\s*/\s*\d+"")),"""")"),"") | H22: =IFERROR(__xludf.DUMMYFUNCTION("IFERROR(VALUE(REGEXEXTRACT(C22,""\d+\s*/\s*(\d+)"")),"""")"),"") | I22: =IF(OR(G22="",H22=""),"",H22-G22) | J22: =IF(OR(D22="",I22=""),"",D22*I22)
A23: NAC | B23: =IF(MOV_CC_NACIONAL!A23="","",MOV_CC_NACIONAL!A23) | C23: =IF(MOV_CC_NACIONAL!B23="","",MOV_CC_NACIONAL!B23) | D23: =IF(MOV_CC_NACIONAL!C23="","",MOV_CC_NACIONAL!C23) | E23: =IF(B23="","", "CLP") | F23: =IFERROR(__xludf.DUMMYFUNCTION("IF(C23="""","""", OR(REGEXMATCH(LOWER(C23),""cuota""), REGEXMATCH(C23,""\d+\s*/\s*\d+"")))"),"") | G23: =IFERROR(__xludf.DUMMYFUNCTION("IFERROR(VALUE(REGEXEXTRACT(C23,""(\d+)\s*/\s*\d+"")),"""")"),"") | H23: =IFERROR(__xludf.DUMMYFUNCTION("IFERROR(VALUE(REGEXEXTRACT(C23,""\d+\s*/\s*(\d+)"")),"""")"),"") | I23: =IF(OR(G23="",H23=""),"",H23-G23) | J23: =IF(OR(D23="",I23=""),"",D23*I23)
A24: NAC | B24: =IF(MOV_CC_NACIONAL!A24="","",MOV_CC_NACIONAL!A24) | C24: =IF(MOV_CC_NACIONAL!B24="","",MOV_CC_NACIONAL!B24) | D24: =IF(MOV_CC_NACIONAL!C24="","",MOV_CC_NACIONAL!C24) | E24: =IF(B24="","", "CLP") | F24: =IFERROR(__xludf.DUMMYFUNCTION("IF(C24="""","""", OR(REGEXMATCH(LOWER(C24),""cuota""), REGEXMATCH(C24,""\d+\s*/\s*\d+"")))"),"") | G24: =IFERROR(__xludf.DUMMYFUNCTION("IFERROR(VALUE(REGEXEXTRACT(C24,""(\d+)\s*/\s*\d+"")),"""")"),"") | H24: =IFERROR(__xludf.DUMMYFUNCTION("IFERROR(VALUE(REGEXEXTRACT(C24,""\d+\s*/\s*(\d+)"")),"""")"),"") | I24: =IF(OR(G24="",H24=""),"",H24-G24) | J24: =IF(OR(D24="",I24=""),"",D24*I24)
A25: NAC | B25: =IF(MOV_CC_NACIONAL!A25="","",MOV_CC_NACIONAL!A25) | C25: =IF(MOV_CC_NACIONAL!B25="","",MOV_CC_NACIONAL!B25) | D25: =IF(MOV_CC_NACIONAL!C25="","",MOV_CC_NACIONAL!C25) | E25: =IF(B25="","", "CLP") | F25: =IFERROR(__xludf.DUMMYFUNCTION("IF(C25="""","""", OR(REGEXMATCH(LOWER(C25),""cuota""), REGEXMATCH(C25,""\d+\s*/\s*\d+"")))"),"") | G25: =IFERROR(__xludf.DUMMYFUNCTION("IFERROR(VALUE(REGEXEXTRACT(C25,""(\d+)\s*/\s*\d+"")),"""")"),"") | H25: =IFERROR(__xludf.DUMMYFUNCTION("IFERROR(VALUE(REGEXEXTRACT(C25,""\d+\s*/\s*(\d+)"")),"""")"),"") | I25: =IF(OR(G25="",H25=""),"",H25-G25) | J25: =IF(OR(D25="",I25=""),"",D25*I25)
A26: NAC | B26: =IF(MOV_CC_NACIONAL!A26="","",MOV_CC_NACIONAL!A26) | C26: =IF(MOV_CC_NACIONAL!B26="","",MOV_CC_NACIONAL!B26) | D26: =IF(MOV_CC_NACIONAL!C26="","",MOV_CC_NACIONAL!C26) | E26: =IF(B26="","", "CLP") | F26: =IFERROR(__xludf.DUMMYFUNCTION("IF(C26="""","""", OR(REGEXMATCH(LOWER(C26),""cuota""), REGEXMATCH(C26,""\d+\s*/\s*\d+"")))"),"") | G26: =IFERROR(__xludf.DUMMYFUNCTION("IFERROR(VALUE(REGEXEXTRACT(C26,""(\d+)\s*/\s*\d+"")),"""")"),"") | H26: =IFERROR(__xludf.DUMMYFUNCTION("IFERROR(VALUE(REGEXEXTRACT(C26,""\d+\s*/\s*(\d+)"")),"""")"),"") | I26: =IF(OR(G26="",H26=""),"",H26-G26) | J26: =IF(OR(D26="",I26=""),"",D26*I26)
A27: NAC | B27: =IF(MOV_CC_NACIONAL!A27="","",MOV_CC_NACIONAL!A27) | C27: =IF(MOV_CC_NACIONAL!B27="","",MOV_CC_NACIONAL!B27) | D27: =IF(MOV_CC_NACIONAL!C27="","",MOV_CC_NACIONAL!C27) | E27: =IF(B27="","", "CLP") | F27: =IFERROR(__xludf.DUMMYFUNCTION("IF(C27="""","""", OR(REGEXMATCH(LOWER(C27),""cuota""), REGEXMATCH(C27,""\d+\s*/\s*\d+"")))"),"") | G27: =IFERROR(__xludf.DUMMYFUNCTION("IFERROR(VALUE(REGEXEXTRACT(C27,""(\d+)\s*/\s*\d+"")),"""")"),"") | H27: =IFERROR(__xludf.DUMMYFUNCTION("IFERROR(VALUE(REGEXEXTRACT(C27,""\d+\s*/\s*(\d+)"")),"""")"),"") | I27: =IF(OR(G27="",H27=""),"",H27-G27) | J27: =IF(OR(D27="",I27=""),"",D27*I27)
A28: NAC | B28: =IF(MOV_CC_NACIONAL!A28="","",MOV_CC_NACIONAL!A28) | C28: =IF(MOV_CC_NACIONAL!B28="","",MOV_CC_NACIONAL!B28) | D28: =IF(MOV_CC_NACIONAL!C28="","",MOV_CC_NACIONAL!C28) | E28: =IF(B28="","", "CLP") | F28: =IFERROR(__xludf.DUMMYFUNCTION("IF(C28="""","""", OR(REGEXMATCH(LOWER(C28),""cuota""), REGEXMATCH(C28,""\d+\s*/\s*\d+"")))"),"") | G28: =IFERROR(__xludf.DUMMYFUNCTION("IFERROR(VALUE(REGEXEXTRACT(C28,""(\d+)\s*/\s*\d+"")),"""")"),"") | H28: =IFERROR(__xludf.DUMMYFUNCTION("IFERROR(VALUE(REGEXEXTRACT(C28,""\d+\s*/\s*(\d+)"")),"""")"),"") | I28: =IF(OR(G28="",H28=""),"",H28-G28) | J28: =IF(OR(D28="",I28=""),"",D28*I28)
A29: NAC | B29: =IF(MOV_CC_NACIONAL!A29="","",MOV_CC_NACIONAL!A29) | C29: =IF(MOV_CC_NACIONAL!B29="","",MOV_CC_NACIONAL!B29) | D29: =IF(MOV_CC_NACIONAL!C29="","",MOV_CC_NACIONAL!C29) | E29: =IF(B29="","", "CLP") | F29: =IFERROR(__xludf.DUMMYFUNCTION("IF(C29="""","""", OR(REGEXMATCH(LOWER(C29),""cuota""), REGEXMATCH(C29,""\d+\s*/\s*\d+"")))"),"") | G29: =IFERROR(__xludf.DUMMYFUNCTION("IFERROR(VALUE(REGEXEXTRACT(C29,""(\d+)\s*/\s*\d+"")),"""")"),"") | H29: =IFERROR(__xludf.DUMMYFUNCTION("IFERROR(VALUE(REGEXEXTRACT(C29,""\d+\s*/\s*(\d+)"")),"""")"),"") | I29: =IF(OR(G29="",H29=""),"",H29-G29) | J29: =IF(OR(D29="",I29=""),"",D29*I29)
A30: NAC | B30: =IF(MOV_CC_NACIONAL!A30="","",MOV_CC_NACIONAL!A30) | C30: =IF(MOV_CC_NACIONAL!B30="","",MOV_CC_NACIONAL!B30) | D30: =IF(MOV_CC_NACIONAL!C30="","",MOV_CC_NACIONAL!C30) | E30: =IF(B30="","", "CLP") | F30: =IFERROR(__xludf.DUMMYFUNCTION("IF(C30="""","""", OR(REGEXMATCH(LOWER(C30),""cuota""), REGEXMATCH(C30,""\d+\s*/\s*\d+"")))"),"") | G30: =IFERROR(__xludf.DUMMYFUNCTION("IFERROR(VALUE(REGEXEXTRACT(C30,""(\d+)\s*/\s*\d+"")),"""")"),"") | H30: =IFERROR(__xludf.DUMMYFUNCTION("IFERROR(VALUE(REGEXEXTRACT(C30,""\d+\s*/\s*(\d+)"")),"""")"),"") | I30: =IF(OR(G30="",H30=""),"",H30-G30) | J30: =IF(OR(D30="",I30=""),"",D30*I30)
A31: NAC | B31: =IF(MOV_CC_NACIONAL!A31="","",MOV_CC_NACIONAL!A31) | C31: =IF(MOV_CC_NACIONAL!B31="","",MOV_CC_NACIONAL!B31) | D31: =IF(MOV_CC_NACIONAL!C31="","",MOV_CC_NACIONAL!C31) | E31: =IF(B31="","", "CLP") | F31: =IFERROR(__xludf.DUMMYFUNCTION("IF(C31="""","""", OR(REGEXMATCH(LOWER(C31),""cuota""), REGEXMATCH(C31,""\d+\s*/\s*\d+"")))"),"") | G31: =IFERROR(__xludf.DUMMYFUNCTION("IFERROR(VALUE(REGEXEXTRACT(C31,""(\d+)\s*/\s*\d+"")),"""")"),"") | H31: =IFERROR(__xludf.DUMMYFUNCTION("IFERROR(VALUE(REGEXEXTRACT(C31,""\d+\s*/\s*(\d+)"")),"""")"),"") | I31: =IF(OR(G31="",H31=""),"",H31-G31) | J31: =IF(OR(D31="",I31=""),"",D31*I31)
A32: NAC | B32: =IF(MOV_CC_NACIONAL!A32="","",MOV_CC_NACIONAL!A32) | C32: =IF(MOV_CC_NACIONAL!B32="","",MOV_CC_NACIONAL!B32) | D32: =IF(MOV_CC_NACIONAL!C32="","",MOV_CC_NACIONAL!C32) | E32: =IF(B32="","", "CLP") | F32: =IFERROR(__xludf.DUMMYFUNCTION("IF(C32="""","""", OR(REGEXMATCH(LOWER(C32),""cuota""), REGEXMATCH(C32,""\d+\s*/\s*\d+"")))"),"") | G32: =IFERROR(__xludf.DUMMYFUNCTION("IFERROR(VALUE(REGEXEXTRACT(C32,""(\d+)\s*/\s*\d+"")),"""")"),"") | H32: =IFERROR(__xludf.DUMMYFUNCTION("IFERROR(VALUE(REGEXEXTRACT(C32,""\d+\s*/\s*(\d+)"")),"""")"),"") | I32: =IF(OR(G32="",H32=""),"",H32-G32) | J32: =IF(OR(D32="",I32=""),"",D32*I32)
A33: NAC | B33: =IF(MOV_CC_NACIONAL!A33="","",MOV_CC_NACIONAL!A33) | C33: =IF(MOV_CC_NACIONAL!B33="","",MOV_CC_NACIONAL!B33) | D33: =IF(MOV_CC_NACIONAL!C33="","",MOV_CC_NACIONAL!C33) | E33: =IF(B33="","", "CLP") | F33: =IFERROR(__xludf.DUMMYFUNCTION("IF(C33="""","""", OR(REGEXMATCH(LOWER(C33),""cuota""), REGEXMATCH(C33,""\d+\s*/\s*\d+"")))"),"") | G33: =IFERROR(__xludf.DUMMYFUNCTION("IFERROR(VALUE(REGEXEXTRACT(C33,""(\d+)\s*/\s*\d+"")),"""")"),"") | H33: =IFERROR(__xludf.DUMMYFUNCTION("IFERROR(VALUE(REGEXEXTRACT(C33,""\d+\s*/\s*(\d+)"")),"""")"),"") | I33: =IF(OR(G33="",H33=""),"",H33-G33) | J33: =IF(OR(D33="",I33=""),"",D33*I33)
A34: NAC | B34: =IF(MOV_CC_NACIONAL!A34="","",MOV_CC_NACIONAL!A34) | C34: =IF(MOV_CC_NACIONAL!B34="","",MOV_CC_NACIONAL!B34) | D34: =IF(MOV_CC_NACIONAL!C34="","",MOV_CC_NACIONAL!C34) | E34: =IF(B34="","", "CLP") | F34: =IFERROR(__xludf.DUMMYFUNCTION("IF(C34="""","""", OR(REGEXMATCH(LOWER(C34),""cuota""), REGEXMATCH(C34,""\d+\s*/\s*\d+"")))"),"") | G34: =IFERROR(__xludf.DUMMYFUNCTION("IFERROR(VALUE(REGEXEXTRACT(C34,""(\d+)\s*/\s*\d+"")),"""")"),"") | H34: =IFERROR(__xludf.DUMMYFUNCTION("IFERROR(VALUE(REGEXEXTRACT(C34,""\d+\s*/\s*(\d+)"")),"""")"),"") | I34: =IF(OR(G34="",H34=""),"",H34-G34) | J34: =IF(OR(D34="",I34=""),"",D34*I34)
A35: NAC | B35: =IF(MOV_CC_NACIONAL!A35="","",MOV_CC_NACIONAL!A35) | C35: =IF(MOV_CC_NACIONAL!B35="","",MOV_CC_NACIONAL!B35) | D35: =IF(MOV_CC_NACIONAL!C35="","",MOV_CC_NACIONAL!C35) | E35: =IF(B35="","", "CLP") | F35: =IFERROR(__xludf.DUMMYFUNCTION("IF(C35="""","""", OR(REGEXMATCH(LOWER(C35),""cuota""), REGEXMATCH(C35,""\d+\s*/\s*\d+"")))"),"") | G35: =IFERROR(__xludf.DUMMYFUNCTION("IFERROR(VALUE(REGEXEXTRACT(C35,""(\d+)\s*/\s*\d+"")),"""")"),"") | H35: =IFERROR(__xludf.DUMMYFUNCTION("IFERROR(VALUE(REGEXEXTRACT(C35,""\d+\s*/\s*(\d+)"")),"""")"),"") | I35: =IF(OR(G35="",H35=""),"",H35-G35) | J35: =IF(OR(D35="",I35=""),"",D35*I35)
A36: NAC | B36: =IF(MOV_CC_NACIONAL!A36="","",MOV_CC_NACIONAL!A36) | C36: =IF(MOV_CC_NACIONAL!B36="","",MOV_CC_NACIONAL!B36) | D36: =IF(MOV_CC_NACIONAL!C36="","",MOV_CC_NACIONAL!C36) | E36: =IF(B36="","", "CLP") | F36: =IFERROR(__xludf.DUMMYFUNCTION("IF(C36="""","""", OR(REGEXMATCH(LOWER(C36),""cuota""), REGEXMATCH(C36,""\d+\s*/\s*\d+"")))"),"") | G36: =IFERROR(__xludf.DUMMYFUNCTION("IFERROR(VALUE(REGEXEXTRACT(C36,""(\d+)\s*/\s*\d+"")),"""")"),"") | H36: =IFERROR(__xludf.DUMMYFUNCTION("IFERROR(VALUE(REGEXEXTRACT(C36,""\d+\s*/\s*(\d+)"")),"""")"),"") | I36: =IF(OR(G36="",H36=""),"",H36-G36) | J36: =IF(OR(D36="",I36=""),"",D36*I36)
A37: NAC | B37: =IF(MOV_CC_NACIONAL!A37="","",MOV_CC_NACIONAL!A37) | C37: =IF(MOV_CC_NACIONAL!B37="","",MOV_CC_NACIONAL!B37) | D37: =IF(MOV_CC_NACIONAL!C37="","",MOV_CC_NACIONAL!C37) | E37: =IF(B37="","", "CLP") | F37: =IFERROR(__xludf.DUMMYFUNCTION("IF(C37="""","""", OR(REGEXMATCH(LOWER(C37),""cuota""), REGEXMATCH(C37,""\d+\s*/\s*\d+"")))"),"") | G37: =IFERROR(__xludf.DUMMYFUNCTION("IFERROR(VALUE(REGEXEXTRACT(C37,""(\d+)\s*/\s*\d+"")),"""")"),"") | H37: =IFERROR(__xludf.DUMMYFUNCTION("IFERROR(VALUE(REGEXEXTRACT(C37,""\d+\s*/\s*(\d+)"")),"""")"),"") | I37: =IF(OR(G37="",H37=""),"",H37-G37) | J37: =IF(OR(D37="",I37=""),"",D37*I37)
A38: NAC | B38: =IF(MOV_CC_NACIONAL!A38="","",MOV_CC_NACIONAL!A38) | C38: =IF(MOV_CC_NACIONAL!B38="","",MOV_CC_NACIONAL!B38) | D38: =IF(MOV_CC_NACIONAL!C38="","",MOV_CC_NACIONAL!C38) | E38: =IF(B38="","", "CLP") | F38: =IFERROR(__xludf.DUMMYFUNCTION("IF(C38="""","""", OR(REGEXMATCH(LOWER(C38),""cuota""), REGEXMATCH(C38,""\d+\s*/\s*\d+"")))"),"") | G38: =IFERROR(__xludf.DUMMYFUNCTION("IFERROR(VALUE(REGEXEXTRACT(C38,""(\d+)\s*/\s*\d+"")),"""")"),"") | H38: =IFERROR(__xludf.DUMMYFUNCTION("IFERROR(VALUE(REGEXEXTRACT(C38,""\d+\s*/\s*(\d+)"")),"""")"),"") | I38: =IF(OR(G38="",H38=""),"",H38-G38) | J38: =IF(OR(D38="",I38=""),"",D38*I38)
A39: NAC | B39: =IF(MOV_CC_NACIONAL!A39="","",MOV_CC_NACIONAL!A39) | C39: =IF(MOV_CC_NACIONAL!B39="","",MOV_CC_NACIONAL!B39) | D39: =IF(MOV_CC_NACIONAL!C39="","",MOV_CC_NACIONAL!C39) | E39: =IF(B39="","", "CLP") | F39: =IFERROR(__xludf.DUMMYFUNCTION("IF(C39="""","""", OR(REGEXMATCH(LOWER(C39),""cuota""), REGEXMATCH(C39,""\d+\s*/\s*\d+"")))"),"") | G39: =IFERROR(__xludf.DUMMYFUNCTION("IFERROR(VALUE(REGEXEXTRACT(C39,""(\d+)\s*/\s*\d+"")),"""")"),"") | H39: =IFERROR(__xludf.DUMMYFUNCTION("IFERROR(VALUE(REGEXEXTRACT(C39,""\d+\s*/\s*(\d+)"")),"""")"),"") | I39: =IF(OR(G39="",H39=""),"",H39-G39) | J39: =IF(OR(D39="",I39=""),"",D39*I39)
A40: NAC | B40: =IF(MOV_CC_NACIONAL!A40="","",MOV_CC_NACIONAL!A40) | C40: =IF(MOV_CC_NACIONAL!B40="","",MOV_CC_NACIONAL!B40) | D40: =IF(MOV_CC_NACIONAL!C40="","",MOV_CC_NACIONAL!C40) | E40: =IF(B40="","", "CLP") | F40: =IFERROR(__xludf.DUMMYFUNCTION("IF(C40="""","""", OR(REGEXMATCH(LOWER(C40),""cuota""), REGEXMATCH(C40,""\d+\s*/\s*\d+"")))"),"") | G40: =IFERROR(__xludf.DUMMYFUNCTION("IFERROR(VALUE(REGEXEXTRACT(C40,""(\d+)\s*/\s*\d+"")),"""")"),"") | H40: =IFERROR(__xludf.DUMMYFUNCTION("IFERROR(VALUE(REGEXEXTRACT(C40,""\d+\s*/\s*(\d+)"")),"""")"),"") | I40: =IF(OR(G40="",H40=""),"",H40-G40) | J40: =IF(OR(D40="",I40=""),"",D40*I40)
...

Sheet MOV_CC_NACIONAL
A1: Fecha | B1: Descripcion | C1: Monto_CLP
A2: 25-02-2026 | B2: UBER RIDES UBER RIDES LAS CO | C2: 12931
A3: 25-02-2026 | B3: CHILE DOGS LTDA CON CO | C3: 46990
A4: 24-02-2026 | B4: PAYU *FLIXBUS SANTIA | C4: 6499
A5: 24-02-2026 | B5: PAYU *UBER TRIP SANTIA | C5: 12600
A6: 24-02-2026 | B6: PAYU *FLIXBUS SANTIA | C6: 4999
A7: 24-02-2026 | B7: PAYU *UBER TRIP SANTIA | C7: 6078
A8: 23-02-2026 | B8: MERCADOPAGO*MERCADO COMPRAS | C8: 11980
A9: 23-02-2026 | B9: PAYU *FLIXBUS COMPRAS | C9: 7699
A10: 21-02-2026 | B10: LOCAL EU 15 NORTE COMPRAS | C10: 19990
A11: 21-02-2026 | B11: MORA LOUTIT SWEET S COMPRAS | C11: 11550
A12: 23-02-2026 | B12: MERCADOPAGO*MERCADO 03 CTAS-INT: 0 | C12: 86791
A13: 21-02-2026 | B13: MERPAGO*OPTICASLUXO HUE CC 01-06 | C13: 41030
... A16: 21-01-2026 | B16: MP *MERCADO LIB SAN CC 02-03 | C16: 15295
A17: 46235 | B17: MP *MERCADO LIB SAN CC 03-06 | C17: 20813
A18: 46204 | B18: MERCADOPAGO*STREETD LAS CF 02-06 | C18: 10997
A19: 21-12-2025 | B19: MERPAGO*MERCADOLIBR LAS CC 03-03 | C19: 17538
A20: 28-11-2025 | B20: CIC HOGAR TIENDA CO CON CC 04-06 | C20: 20496
A21: 28-08-2025 | B21: MERCADOPAGO*MONSTER LAS CF 06-06 | C21: 14667

Sheet MOV_CC_INTL
A1: Fecha | B1: Descripcion | C1: Monto_USD
A2: 22-02-2026 | B2: EMBY PREMIERE COMPRAS INT.VI | C2: 4.99
A3: 20-02-2026 | B3: CLAUDE.AI SUBSCRIPT COMPRAS INT.VI | C3: 102.76
A4: 19-02-2026 | B4: APPLE.COM/BILL COMPRAS INT.VI | C4: 12.48

Sheet RESUMEN
A1: Concepto | B1: Total
A2: Compras Nacional (solo >0) | B2: =SUMIF(MOV_NAC_AUTO!C:C,">0") -> 420514
A3: Compras Internacional CLP (solo >0) | B3: =SUMIF(MOV_INTL_AUTO!E:E,">0") -> 114218.5
A4: Pagos/Abonos Nacional (abs <0) | B4: =ABS(SUMIF(MOV_NAC_AUTO!C:C,"<0")) -> 0
A5: Pagos/Abonos Intl CLP (abs <0) | B5: =ABS(SUMIF(MOV_INTL_AUTO!E:E,"<0")) -> 0
A6: Net Nacional (compras - pagos) | B6: =B2-B4 -> 420514
A7: Net Intl CLP (compras - pagos) | B7: =B3-B5 -> 114218.5

Sheet PROYECCION
A1: Concepto | B1: Valor
A2: Ingreso | B2: =CONFIG!B2 -> 3000000
A3: Costos Fijos | B3: =CONFIG!B3+CONFIG!B4 -> 1300000
A4: Compras Nacional | B4: =RESUMEN!B2 -> 420514
A5: Compras Internacional | B5: =RESUMEN!B3 -> 114218.5
A6: Claude Plan | B6: =CONFIG!B6 -> 0
A7: Margen Disponible | B7: =B2-(B3+B4+B5+B6) -> 1165267.5
A8: Total a gastar (fijos+compras+Claude) | B8: =B3+B4+B5+B6 -> 1834732.5
A9: Ahorro sugerido (si hay margen) | B9: =MAX(0,MIN(500000,B7-300000)) -> 500000

Sheet BURN_CURVE
A1: Dia | B1: Liquidez Estimada
A2: 1 | B2: =PROYECCION!B7/30*A2 -> 38842.25
A3: 2 | B3: =PROYECCION!B7/30*A3 -> 77684.5
A4: 3 | B4: =PROYECCION!B7/30*A4 -> 116526.75
A5: 4 | B5: =PROYECCION!B7/30*A5 -> 155369
A6: 5 | B6: =PROYECCION!B7/30*A6 -> 194211.25
A7: 6 | B7: =PROYECCION!B7/30*A7 -> 233053.5
A8: 7 | B8: =PROYECCION!B7/30*A8 -> 271895.75
A9: 8 | B9: =PROYECCION!B7/30*A9 -> 310738
A10: 9 | B10: =PROYECCION!B7/30*A10 -> 349580.25
A11: 10 | B11: =PROYECCION!B7/30*A11 -> 388422.5
A12: 11 | B12: =PROYECCION!B7/30*A12 -> 427264.75
A13: 12 | B13: =PROYECCION!B7/30*A13 -> 466107
A14: 13 | B14: =PROYECCION!B7/30*A14 -> 504949.25
A15: 14 | B15: =PROYECCION!B7/30*A15 -> 543791.5
A16: 15 | B16: =PROYECCION!B7/30*A16 -> 582633.75
A17: 16 | B17: =PROYECCION!B7/30*A17 -> 621476
A18: 17 | B18: =PROYECCION!B7/30*A18 -> 660318.25
A19: 18 | B19: =PROYECCION!B7/30*A19 -> 699160.5
A20: 19 | B20: =PROYECCION!B7/30*A20 -> 738002.75
A21: 20 | B21: =PROYECCION!B7/30*A21 -> 776845
A22: 21 | B22: =PROYECCION!B7/30*A22 -> 815687.25
A23: 22 | B23: =PROYECCION!B7/30*A23 -> 854529.5
A24: 23 | B24: =PROYECCION!B7/30*A24 -> 893371.75
A25: 24 | B25: =PROYECCION!B7/30*A25 -> 932214
A26: 25 | B26: =PROYECCION!B7/30*A26 -> 971056.25
A27: 26 | B27: =PROYECCION!B7/30*A27 -> 1009898.5
A28: 27 | B28: =PROYECCION!B7/30*A28 -> 1048740.8
A29: 28 | B29: =PROYECCION!B7/30*A29 -> 1087583
A30: 29 | B30: =PROYECCION!B7/30*A30 -> 1126425.2
A31: 30 | B31: =PROYECCION!B7/30*A31 -> 1165267.5

Sheet CATEGORIAS
A1: Tipo | B1: Keyword (contains) | C1: Categoria
A2: NAC | B2: uber | C2: Food & Transport
A3: NAC | B3: payu *uber | C3: Food & Transport
A4: NAC | B4: kfc | C4: Food & Transport
A5: NAC | B5: cinemark | C5: Food & Transport
A6: NAC | B6: pethouse | C6: Pets & Health
A7: NAC | B7: superzoo | C7: Pets & Health
A8: NAC | B8: servicios medicos | C8: Pets & Health
A9: NAC | B9: farm | C9: Pharmacy
A10: NAC | B10: cruz verde | C10: Pharmacy
A11: NAC | B11: mercado | C11: Shopping
A12: NAC | B12: mercadopago | C12: Shopping
... A21: INTL | B21: battle | C21: Gaming

Sheet MOV_NAC_AUTO
A1: Fecha | B1: Descripcion | C1: Monto_CLP | D1: Categoria
A2: =IF(MOV_CC_NACIONAL!A2="","",MOV_CC_NACIONAL!A2) -> 25-02-2026 | B2: =IF(MOV_CC_NACIONAL!B2="","",MOV_CC_NACIONAL!B2) -> UBER RIDES UBER RIDES LAS CO | C2: =IF(MOV_CC_NACIONAL!C2="","",MOV_CC_NACIONAL!C2) -> 12931 | D2: =IF(ISNUMBER(SEARCH("uber",LOWER(B2))),"Food & Transport",IF(ISNUMBER(SEARCH("payu *uber",LOWER(B2))),"Food & Transport",IF(ISNUMBER(SEARCH("kfc",LOWER(B2))),"Food & Transport",IF(ISNUMBER(SEARCH("cinemark",LOWER(B2))),"Food & Transport",IF(ISNUMBER(SEARCH("pethouse",LOWER(B2))),"Pets & Health",IF(ISNUMBER(SEARCH("superzoo",LOWER(B2))),"Pets & Health",IF(ISNUMBER(SEARCH("servicios medicos",LOWER(B2))),"Pets & Health",IF(ISNUMBER(SEARCH("farm",LOWER(B2))),"Pharmacy",IF(ISNUMBER(SEARCH("cruz verde",LOWER(B2))),"Pharmacy",IF(ISNUMBER(SEARCH("mercado",LOWER(B2))),"Shopping",IF(ISNUMBER(SEARCH("mercadopago",LOWER(B2))),"Shopping",IF(ISNUMBER(SEARCH("ikea",LOWER(B2))),"Shopping",IF(ISNUMBER(SEARCH("spotify",LOWER(B2))),"Subscriptions","Other"))))))))))))) -> Food & Transport
A3: =IF(MOV_CC_NACIONAL!A3="","",MOV_CC_NACIONAL!A3) -> 25-02-2026 | B3: =IF(MOV_CC_NACIONAL!B3="","",MOV_CC_NACIONAL!B3) -> CHILE DOGS LTDA CON CO | C3: =IF(MOV_CC_NACIONAL!C3="","",MOV_CC_NACIONAL!C3) -> 46990 | D3: =IF(ISNUMBER(SEARCH("uber",LOWER(B3))),"Food & Transport",IF(ISNUMBER(SEARCH("payu *uber",LOWER(B3))),"Food & Transport",IF(ISNUMBER(SEARCH("kfc",LOWER(B3))),"Food & Transport",IF(ISNUMBER(SEARCH("cinemark",LOWER(B3))),"Food & Transport",IF(ISNUMBER(SEARCH("pethouse",LOWER(B3))),"Pets & Health",IF(ISNUMBER(SEARCH("superzoo",LOWER(B3))),"Pets & Health",IF(ISNUMBER(SEARCH("servicios medicos",LOWER(B3))),"Pets & Health",IF(ISNUMBER(SEARCH("farm",LOWER(B3))),"Pharmacy",IF(ISNUMBER(SEARCH("cruz verde",LOWER(B3))),"Pharmacy",IF(ISNUMBER(SEARCH("mercado",LOWER(B3))),"Shopping",IF(ISNUMBER(SEARCH("mercadopago",LOWER(B3))),"Shopping",IF(ISNUMBER(SEARCH("ikea",LOWER(B3))),"Shopping",IF(ISNUMBER(SEARCH("spotify",LOWER(B3))),"Subscriptions","Other"))))))))))))) -> Other
A4: =IF(MOV_CC_NACIONAL!A4="","",MOV_CC_NACIONAL!A4) -> 24-02-2026 | B4: =IF(MOV_CC_NACIONAL!B4="","",MOV_CC_NACIONAL!B4) -> PAYU *FLIXBUS SANTIA | C4: =IF(MOV_CC_NACIONAL!C4="","",MOV_CC_NACIONAL!C4) -> 6499 | D4: =IF(ISNUMBER(SEARCH("uber",LOWER(B4))),"Food & Transport",IF(ISNUMBER(SEARCH("payu *uber",LOWER(B4))),"Food & Transport",IF(ISNUMBER(SEARCH("kfc",LOWER(B4))),"Food & Transport",IF(ISNUMBER(SEARCH("cinemark",LOWER(B4))),"Food & Transport",IF(ISNUMBER(SEARCH("pethouse",LOWER(B4))),"Pets & Health",IF(ISNUMBER(SEARCH("superzoo",LOWER(B4))),"Pets & Health",IF(ISNUMBER(SEARCH("servicios medicos",LOWER(B4))),"Pets & Health",IF(ISNUMBER(SEARCH("farm",LOWER(B4))),"Pharmacy",IF(ISNUMBER(SEARCH("cruz verde",LOWER(B4))),"Pharmacy",IF(ISNUMBER(SEARCH("mercado",LOWER(B4))),"Shopping",IF(ISNUMBER(SEARCH("mercadopago",LOWER(B4))),"Shopping",IF(ISNUMBER(SEARCH("ikea",LOWER(B4))),"Shopping",IF(ISNUMBER(SEARCH("spotify",LOWER(B4))),"Subscriptions","Other"))))))))))))) -> Other
A5: =IF(MOV_CC_NACIONAL!A5="","",MOV_CC_NACIONAL!A5) -> 24-02-2026 | B5: =IF(MOV_CC_NACIONAL!B5="","",MOV_CC_NACIONAL!B5) -> PAYU *UBER TRIP SANTIA | C5: =IF(MOV_CC_NACIONAL!C5="","",MOV_CC_NACIONAL!C5) -> 12600 | D5: =IF(ISNUMBER(SEARCH("uber",LOWER(B5))),"Food & Transport",IF(ISNUMBER(SEARCH("payu *uber",LOWER(B5))),"Food & Transport",IF(ISNUMBER(SEARCH("kfc",LOWER(B5))),"Food & Transport",IF(ISNUMBER(SEARCH("cinemark",LOWER(B5))),"Food & Transport",IF(ISNUMBER(SEARCH("pethouse",LOWER(B5))),"Pets & Health",IF(ISNUMBER(SEARCH("superzoo",LOWER(B5))),"Pets & Health",IF(ISNUMBER(SEARCH("servicios medicos",LOWER(B5))),"Pets & Health",IF(ISNUMBER(SEARCH("farm",LOWER(B5))),"Pharmacy",IF(ISNUMBER(SEARCH("cruz verde",LOWER(B5))),"Pharmacy",IF(ISNUMBER(SEARCH("mercado",LOWER(B5))),"Shopping",IF(ISNUMBER(SEARCH("mercadopago",LOWER(B5))),"Shopping",IF(ISNUMBER(SEARCH("ikea",LOWER(B5))),"Shopping",IF(ISNUMBER(SEARCH("spotify",LOWER(B5))),"Subscriptions","Other"))))))))))))) -> Food & Transport
A6: =IF(MOV_CC_NACIONAL!A6="","",MOV_CC_NACIONAL!A6) -> 24-02-2026 | B6: =IF(MOV_CC_NACIONAL!B6="","",MOV_CC_NACIONAL!B6) -> PAYU *FLIXBUS SANTIA | C6: =IF(MOV_CC_NACIONAL!C6="","",MOV_CC_NACIONAL!C6) -> 4999 | D6: =IF(ISNUMBER(SEARCH("uber",LOWER(B6))),"Food & Transport",IF(ISNUMBER(SEARCH("payu *uber",LOWER(B6))),"Food & Transport",IF(ISNUMBER(SEARCH("kfc",LOWER(B6))),"Food & Transport",IF(ISNUMBER(SEARCH("cinemark",LOWER(B6))),"Food & Transport",IF(ISNUMBER(SEARCH("pethouse",LOWER(B6))),"Pets & Health",IF(ISNUMBER(SEARCH("superzoo",LOWER(B6))),"Pets & Health",IF(ISNUMBER(SEARCH("servicios medicos",LOWER(B6))),"Pets & Health",IF(ISNUMBER(SEARCH("farm",LOWER(B6))),"Pharmacy",IF(ISNUMBER(SEARCH("cruz verde",LOWER(B6))),"Pharmacy",IF(ISNUMBER(SEARCH("mercado",LOWER(B6))),"Shopping",IF(ISNUMBER(SEARCH("mercadopago",LOWER(B6))),"Shopping",IF(ISNUMBER(SEARCH("ikea",LOWER(B6))),"Shopping",IF(ISNUMBER(SEARCH("spotify",LOWER(B6))),"Subscriptions","Other"))))))))))))) -> Other
A7: =IF(MOV_CC_NACIONAL!A7="","",MOV_CC_NACIONAL!A7) -> 24-02-2026 | B7: =IF(MOV_CC_NACIONAL!B7="","",MOV_CC_NACIONAL!B7) -> PAYU *UBER TRIP SANTIA | C7: =IF(MOV_CC_NACIONAL!C7="","",MOV_CC_NACIONAL!C7) -> 6078 | D7: =IF(ISNUMBER(SEARCH("uber",LOWER(B7))),"Food & Transport",IF(ISNUMBER(SEARCH("payu *uber",LOWER(B7))),"Food & Transport",IF(ISNUMBER(SEARCH("kfc",LOWER(B7))),"Food & Transport",IF(ISNUMBER(SEARCH("cinemark",LOWER(B7))),"Food & Transport",IF(ISNUMBER(SEARCH("pethouse",LOWER(B7))),"Pets & Health",IF(ISNUMBER(SEARCH("superzoo",LOWER(B7))),"Pets & Health",IF(ISNUMBER(SEARCH("servicios medicos",LOWER(B7))),"Pets & Health",IF(ISNUMBER(SEARCH("farm",LOWER(B7))),"Pharmacy",IF(ISNUMBER(SEARCH("cruz verde",LOWER(B7))),"Pharmacy",IF(ISNUMBER(SEARCH("mercado",LOWER(B7))),"Shopping",IF(ISNUMBER(SEARCH("mercadopago",LOWER(B7))),"Shopping",IF(ISNUMBER(SEARCH("ikea",LOWER(B7))),"Shopping",IF(ISNUMBER(SEARCH("spotify",LOWER(B7))),"Subscriptions","Other"))))))))))))) -> Food & Transport
A8: =IF(MOV_CC_NACIONAL!A8="","",MOV_CC_NACIONAL!A8) -> 23-02-2026 | B8: =IF(MOV_CC_NACIONAL!B8="","",MOV_CC_NACIONAL!B8) -> MERCADOPAGO*MERCADO COMPRAS | C8: =IF(MOV_CC_NACIONAL!C8="","",MOV_CC_NACIONAL!C8) -> 11980 | D8: =IF(ISNUMBER(SEARCH("uber",LOWER(B8))),"Food & Transport",IF(ISNUMBER(SEARCH("payu *uber",LOWER(B8))),"Food & Transport",IF(ISNUMBER(SEARCH("kfc",LOWER(B8))),"Food & Transport",IF(ISNUMBER(SEARCH("cinemark",LOWER(B8))),"Food & Transport",IF(ISNUMBER(SEARCH("pethouse",LOWER(B8))),"Pets & Health",IF(ISNUMBER(SEARCH("superzoo",LOWER(B8))),"Pets & Health",IF(ISNUMBER(SEARCH("servicios medicos",LOWER(B8))),"Pets & Health",IF(ISNUMBER(SEARCH("farm",LOWER(B8))),"Pharmacy",IF(ISNUMBER(SEARCH("cruz verde",LOWER(B8))),"Pharmacy",IF(ISNUMBER(SEARCH("mercado",LOWER(B8))),"Shopping",IF(ISNUMBER(SEARCH("mercadopago",LOWER(B8))),"Shopping",IF(ISNUMBER(SEARCH("ikea",LOWER(B8))),"Shopping",IF(ISNUMBER(SEARCH("spotify",LOWER(B8))),"Subscriptions","Other"))))))))))))) -> Shopping
A9: =IF(MOV_CC_NACIONAL!A9="","",MOV_CC_NACIONAL!A9) -> 23-02-2026 | B9: =IF(MOV_CC_NACIONAL!B9="","",MOV_CC_NACIONAL!B9) -> PAYU *FLIXBUS COMPRAS | C9: =IF(MOV_CC_NACIONAL!C9="","",MOV_CC_NACIONAL!C9) -> 7699 | D9: =IF(ISNUMBER(SEARCH("uber",LOWER(B9))),"Food & Transport",IF(ISNUMBER(SEARCH("payu *uber",LOWER(B9))),"Food & Transport",IF(ISNUMBER(SEARCH("kfc",LOWER(B9))),"Food & Transport",IF(ISNUMBER(SEARCH("cinemark",LOWER(B9))),"Food & Transport",IF(ISNUMBER(SEARCH("pethouse",LOWER(B9))),"Pets & Health",IF(ISNUMBER(SEARCH("superzoo",LOWER(B9))),"Pets & Health",IF(ISNUMBER(SEARCH("servicios medicos",LOWER(B9))),"Pets & Health",IF(ISNUMBER(SEARCH("farm",LOWER(B9))),"Pharmacy",IF(ISNUMBER(SEARCH("cruz verde",LOWER(B9))),"Pharmacy",IF(ISNUMBER(SEARCH("mercado",LOWER(B9))),"Shopping",IF(ISNUMBER(SEARCH("mercadopago",LOWER(B9))),"Shopping",IF(ISNUMBER(SEARCH("ikea",LOWER(B9))),"Shopping",IF(ISNUMBER(SEARCH("spotify",LOWER(B9))),"Subscriptions","Other"))))))))))))) -> Other
A10: =IF(MOV_CC_NACIONAL!A10="","",MOV_CC_NACIONAL!A10) -> 21-02-2026 | B10: =IF(MOV_CC_NACIONAL!B10="","",MOV_CC_NACIONAL!B10) -> LOCAL EU 15 NORTE COMPRAS | C10: =IF(MOV_CC_NACIONAL!C10="","",MOV_CC_NACIONAL!C10) -> 19990 | D10: =IF(ISNUMBER(SEARCH("uber",LOWER(B10))),"Food & Transport",IF(ISNUMBER(SEARCH("payu *uber",LOWER(B10))),"Food & Transport",IF(ISNUMBER(SEARCH("kfc",LOWER(B10))),"Food & Transport",IF(ISNUMBER(SEARCH("cinemark",LOWER(B10))),"Food & Transport",IF(ISNUMBER(SEARCH("pethouse",LOWER(B10))),"Pets & Health",IF(ISNUMBER(SEARCH("superzoo",LOWER(B10))),"Pets & Health",IF(ISNUMBER(SEARCH("servicios medicos",LOWER(B10))),"Pets & Health",IF(ISNUMBER(SEARCH("farm",LOWER(B10))),"Pharmacy",IF(ISNUMBER(SEARCH("cruz verde",LOWER(B10))),"Pharmacy",IF(ISNUMBER(SEARCH("mercado",LOWER(B10))),"Shopping",IF(ISNUMBER(SEARCH("mercadopago",LOWER(B10))),"Shopping",IF(ISNUMBER(SEARCH("ikea",LOWER(B10))),"Shopping",IF(ISNUMBER(SEARCH("spotify",LOWER(B10))),"Subscriptions","Other"))))))))))))) -> Other
A11: =IF(MOV_CC_NACIONAL!A11="","",MOV_CC_NACIONAL!A11) -> 21-02-2026 | B11: =IF(MOV_CC_NACIONAL!B11="","",MOV_CC_NACIONAL!B11) -> MORA LOUTIT SWEET S COMPRAS | C11: =IF(MOV_CC_NACIONAL!C11="","",MOV_CC_NACIONAL!C11) -> 11550 | D11: =IF(ISNUMBER(SEARCH("uber",LOWER(B11))),"Food & Transport",IF(ISNUMBER(SEARCH("payu *uber",LOWER(B11))),"Food & Transport",IF(ISNUMBER(SEARCH("kfc",LOWER(B11))),"Food & Transport",IF(ISNUMBER(SEARCH("cinemark",LOWER(B11))),"Food & Transport",IF(ISNUMBER(SEARCH("pethouse",LOWER(B11))),"Pets & Health",IF(ISNUMBER(SEARCH("superzoo",LOWER(B11))),"Pets & Health",IF(ISNUMBER(SEARCH("servicios medicos",LOWER(B11))),"Pets & Health",IF(ISNUMBER(SEARCH("farm",LOWER(B11))),"Pharmacy",IF(ISNUMBER(SEARCH("cruz verde",LOWER(B11))),"Pharmacy",IF(ISNUMBER(SEARCH("mercado",LOWER(B11))),"Shopping",IF(ISNUMBER(SEARCH("mercadopago",LOWER(B11))),"Shopping",IF(ISNUMBER(SEARCH("ikea",LOWER(B11))),"Shopping",IF(ISNUMBER(SEARCH("spotify",LOWER(B11))),"Subscriptions","Other"))))))))))))) -> Other
A12: =IF(MOV_CC_NACIONAL!A12="","",MOV_CC_NACIONAL!A12) -> 23-02-2026 | B12: =IF(MOV_CC_NACIONAL!B12="","",MOV_CC_NACIONAL!B12) -> MERCADOPAGO*MERCADO 03 CTAS-INT: 0 | C12: =IF(MOV_CC_NACIONAL!C12="","",MOV_CC_NACIONAL!C12) -> 86791 | D12: =IF(ISNUMBER(SEARCH("uber",LOWER(B12))),"Food & Transport",IF(ISNUMBER(SEARCH("payu *uber",LOWER(B12))),"Food & Transport",IF(ISNUMBER(SEARCH("kfc",LOWER(B12))),"Food & Transport",IF(ISNUMBER(SEARCH("cinemark",LOWER(B12))),"Food & Transport",IF(ISNUMBER(SEARCH("pethouse",LOWER(B12))),"Pets & Health",IF(ISNUMBER(SEARCH("superzoo",LOWER(B12))),"Pets & Health",IF(ISNUMBER(SEARCH("servicios medicos",LOWER(B12))),"Pets & Health",IF(ISNUMBER(SEARCH("farm",LOWER(B12))),"Pharmacy",IF(ISNUMBER(SEARCH("cruz verde",LOWER(B12))),"Pharmacy",IF(ISNUMBER(SEARCH("mercado",LOWER(B12))),"Shopping",IF(ISNUMBER(SEARCH("mercadopago",LOWER(B12))),"Shopping",IF(ISNUMBER(SEARCH("ikea",LOWER(B12))),"Shopping",IF(ISNUMBER(SEARCH("spotify",LOWER(B12))),"Subscriptions","Other"))))))))))))) -> Shopping
A13: =IF(MOV_CC_NACIONAL!A13="","",MOV_CC_NACIONAL!A13) -> 21-02-2026 | B13: =IF(MOV_CC_NACIONAL!B13="","",MOV_CC_NACIONAL!B13) -> MERPAGO*OPTICASLUXO HUE CC 01-06 | C13: =IF(MOV_CC_NACIONAL!C13="","",MOV_CC_NACIONAL!C13) -> 41030 | D13: =IF(ISNUMBER(SEARCH("uber",LOWER(B13))),"Food & Transport",IF(ISNUMBER(SEARCH("payu *uber",LOWER(B13))),"Food & Transport",IF(ISNUMBER(SEARCH("kfc",LOWER(B13))),"Food & Transport",IF(ISNUMBER(SEARCH("cinemark",LOWER(B13))),"Food & Transport",IF(ISNUMBER(SEARCH("pethouse",LOWER(B13))),"Pets & Health",IF(ISNUMBER(SEARCH("superzoo",LOWER(B13))),"Pets & Health",IF(ISNUMBER(SEARCH("servicios medicos",LOWER(B13))),"Pets & Health",IF(ISNUMBER(SEARCH("farm",LOWER(B13))),"Pharmacy",IF(ISNUMBER(SEARCH("cruz verde",LOWER(B13))),"Pharmacy",IF(ISNUMBER(SEARCH("mercado",LOWER(B13))),"Shopping",IF(ISNUMBER(SEARCH("mercadopago",LOWER(B13))),"Shopping",IF(ISNUMBER(SEARCH("ikea",LOWER(B13))),"Shopping",IF(ISNUMBER(SEARCH("spotify",LOWER(B13))),"Subscriptions","Other"))))))))))))) -> Other
... A2001: =IF(MOV_CC_NACIONAL!A2001="","",MOV_CC_NACIONAL!A2001) | B2001: =IF(MOV_CC_NACIONAL!B2001="","",MOV_CC_NACIONAL!B2001) | C2001: =IF(MOV_CC_NACIONAL!C2001="","",MOV_CC_NACIONAL!C2001) | D2001: =IF(ISNUMBER(SEARCH("uber",LOWER(B2001))),"Food & Transport",IF(ISNUMBER(SEARCH("payu *uber",LOWER(B2001))),"Food & Transport",IF(ISNUMBER(SEARCH("kfc",LOWER(B2001))),"Food & Transport",IF(ISNUMBER(SEARCH("cinemark",LOWER(B2001))),"Food & Transport",IF(ISNUMBER(SEARCH("pethouse",LOWER(B2001))),"Pets & Health",IF(ISNUMBER(SEARCH("superzoo",LOWER(B2001))),"Pets & Health",IF(ISNUMBER(SEARCH("servicios medicos",LOWER(B2001))),"Pets & Health",IF(ISNUMBER(SEARCH("farm",LOWER(B2001))),"Pharmacy",IF(ISNUMBER(SEARCH("cruz verde",LOWER(B2001))),"Pharmacy",IF(ISNUMBER(SEARCH("mercado",LOWER(B2001))),"Shopping",IF(ISNUMBER(SEARCH("mercadopago",LOWER(B2001))),"Shopping",IF(ISNUMBER(SEARCH("ikea",LOWER(B2001))),"Shopping",IF(ISNUMBER(SEARCH("spotify",LOWER(B2001))),"Subscriptions","Other"))))))))))))) -> Other

Sheet MOV_INTL_AUTO
A1: Fecha | B1: Descripcion | C1: Monto_USD | D1: Categoria | E1: Monto_CLP_est
A2: =IF(MOV_CC_INTL!A2="","",MOV_CC_INTL!A2) -> 22-02-2026 | B2: =IF(MOV_CC_INTL!B2="","",MOV_CC_INTL!B2) -> EMBY PREMIERE COMPRAS INT.VI | C2: =IF(MOV_CC_INTL!C2="","",MOV_CC_INTL!C2) -> 4.99 | D2: =IF(ISNUMBER(SEARCH("openai",LOWER(B2))),"AI Tools",IF(ISNUMBER(SEARCH("anthropic",LOWER(B2))),"AI Tools",IF(ISNUMBER(SEARCH("claude",LOWER(B2))),"AI Tools",IF(ISNUMBER(SEARCH("appbox",LOWER(B2))),"Digital Services",IF(ISNUMBER(SEARCH("apple",LOWER(B2))),"Digital Services",IF(ISNUMBER(SEARCH("playstation",LOWER(B2))),"Digital Services",IF(ISNUMBER(SEARCH("battle",LOWER(B2))),"Gaming","Other"))))))) -> Other | E2: =IF(C2="","",C2*CONFIG!B5) -> 4740.5
A3: =IF(MOV_CC_INTL!A3="","",MOV_CC_INTL!A3) -> 20-02-2026 | B3: =IF(MOV_CC_INTL!B3="","",MOV_CC_INTL!B3) -> CLAUDE.AI SUBSCRIPT COMPRAS INT.VI | C3: =IF(MOV_CC_INTL!C3="","",MOV_CC_INTL!C3) -> 102.76 | D3: =IF(ISNUMBER(SEARCH("openai",LOWER(B3))),"AI Tools",IF(ISNUMBER(SEARCH("anthropic",LOWER(B3))),"AI Tools",IF(ISNUMBER(SEARCH("claude",LOWER(B3))),"AI Tools",IF(ISNUMBER(SEARCH("appbox",LOWER(B3))),"Digital Services",IF(ISNUMBER(SEARCH("apple",LOWER(B3))),"Digital Services",IF(ISNUMBER(SEARCH("playstation",LOWER(B3))),"Digital Services",IF(ISNUMBER(SEARCH("battle",LOWER(B3))),"Gaming","Other"))))))) -> AI Tools | E3: =IF(C3="","",C3*CONFIG!B5) -> 97622
A4: =IF(MOV_CC_INTL!A4="","",MOV_CC_INTL!A4) -> 19-02-2026 | B4: =IF(MOV_CC_INTL!B4="","",MOV_CC_INTL!B4) -> APPLE.COM/BILL COMPRAS INT.VI | C4: =IF(MOV_CC_INTL!C4="","",MOV_CC_INTL!C4) -> 12.48 | D4: =IF(ISNUMBER(SEARCH("openai",LOWER(B4))),"AI Tools",IF(ISNUMBER(SEARCH("anthropic",LOWER(B4))),"AI Tools",IF(ISNUMBER(SEARCH("claude",LOWER(B4))),"AI Tools",IF(ISNUMBER(SEARCH("appbox",LOWER(B4))),"Digital Services",IF(ISNUMBER(SEARCH("apple",LOWER(B4))),"Digital Services",IF(ISNUMBER(SEARCH("playstation",LOWER(B4))),"Digital Services",IF(ISNUMBER(SEARCH("battle",LOWER(B4))),"Gaming","Other"))))))) -> Digital Services | E4: =IF(C4="","",C4*CONFIG!B5) -> 11856
A5: =IF(MOV_CC_INTL!A5="","",MOV_CC_INTL!A5) | B5: =IF(MOV_CC_INTL!B5="","",MOV_CC_INTL!B5) | C5: =IF(MOV_CC_INTL!C5="","",MOV_CC_INTL!C5) | D5: =IF(ISNUMBER(SEARCH("openai",LOWER(B5))),"AI Tools",IF(ISNUMBER(SEARCH("anthropic",LOWER(B5))),"AI Tools",IF(ISNUMBER(SEARCH("claude",LOWER(B5))),"AI Tools",IF(ISNUMBER(SEARCH("appbox",LOWER(B5))),"Digital Services",IF(ISNUMBER(SEARCH("apple",LOWER(B5))),"Digital Services",IF(ISNUMBER(SEARCH("playstation",LOWER(B5))),"Digital Services",IF(ISNUMBER(SEARCH("battle",LOWER(B5))),"Gaming","Other"))))))) -> Other | E5: =IF(C5="","",C5*CONFIG!B5)
A6: =IF(MOV_CC_INTL!A6="","",MOV_CC_INTL!A6) | B6: =IF(MOV_CC_INTL!B6="","",MOV_CC_INTL!B6) | C6: =IF(MOV_CC_INTL!C6="","",MOV_CC_INTL!C6) | D6: =IF(ISNUMBER(SEARCH("openai",LOWER(B6))),"AI Tools",IF(ISNUMBER(SEARCH("anthropic",LOWER(B6))),"AI Tools",IF(ISNUMBER(SEARCH("claude",LOWER(B6))),"AI Tools",IF(ISNUMBER(SEARCH("appbox",LOWER(B6))),"Digital Services",IF(ISNUMBER(SEARCH("apple",LOWER(B6))),"Digital Services",IF(ISNUMBER(SEARCH("playstation",LOWER(B6))),"Digital Services",IF(ISNUMBER(SEARCH("battle",LOWER(B6))),"Gaming","Other"))))))) -> Other | E6: =IF(C6="","",C6*CONFIG!B5)
A7: =IF(MOV_CC_INTL!A7="","",MOV_CC_INTL!A7) | B7: =IF(MOV_CC_INTL!B7="","",MOV_CC_INTL!B7) | C7: =IF(MOV_CC_INTL!C7="","",MOV_CC_INTL!C7) | D7: =IF(ISNUMBER(SEARCH("openai",LOWER(B7))),"AI Tools",IF(ISNUMBER(SEARCH("anthropic",LOWER(B7))),"AI Tools",IF(ISNUMBER(SEARCH("claude",LOWER(B7))),"AI Tools",IF(ISNUMBER(SEARCH("appbox",LOWER(B7))),"Digital Services",IF(ISNUMBER(SEARCH("apple",LOWER(B7))),"Digital Services",IF(ISNUMBER(SEARCH("playstation",LOWER(B7))),"Digital Services",IF(ISNUMBER(SEARCH("battle",LOWER(B7))),"Gaming","Other"))))))) -> Other | E7: =IF(C7="","",C7*CONFIG!B5)
A8: =IF(MOV_CC_INTL!A8="","",MOV_CC_INTL!A8) | B8: =IF(MOV_CC_INTL!B8="","",MOV_CC_INTL!B8) | C8: =IF(MOV_CC_INTL!C8="","",MOV_CC_INTL!C8) | D8: =IF(ISNUMBER(SEARCH("openai",LOWER(B8))),"AI Tools",IF(ISNUMBER(SEARCH("anthropic",LOWER(B8))),"AI Tools",IF(ISNUMBER(SEARCH("claude",LOWER(B8))),"AI Tools",IF(ISNUMBER(SEARCH("appbox",LOWER(B8))),"Digital Services",IF(ISNUMBER(SEARCH("apple",LOWER(B8))),"Digital Services",IF(ISNUMBER(SEARCH("playstation",LOWER(B8))),"Digital Services",IF(ISNUMBER(SEARCH("battle",LOWER(B8))),"Gaming","Other"))))))) -> Other | E8: =IF(C8="","",C8*CONFIG!B5)
A9: =IF(MOV_CC_INTL!A9="","",MOV_CC_INTL!A9) | B9: =IF(MOV_CC_INTL!B9="","",MOV_CC_INTL!B9) | C9: =IF(MOV_CC_INTL!C9="","",MOV_CC_INTL!C9) | D9: =IF(ISNUMBER(SEARCH("openai",LOWER(B9))),"AI Tools",IF(ISNUMBER(SEARCH("anthropic",LOWER(B9))),"AI Tools",IF(ISNUMBER(SEARCH("claude",LOWER(B9))),"AI Tools",IF(ISNUMBER(SEARCH("appbox",LOWER(B9))),"Digital Services",IF(ISNUMBER(SEARCH("apple",LOWER(B9))),"Digital Services",IF(ISNUMBER(SEARCH("playstation",LOWER(B9))),"Digital Services",IF(ISNUMBER(SEARCH("battle",LOWER(B9))),"Gaming","Other"))))))) -> Other | E9: =IF(C9="","",C9*CONFIG!B5)
A10: =IF(MOV_CC_INTL!A10="","",MOV_CC_INTL!A10) | B10: =IF(MOV_CC_INTL!B10="","",MOV_CC_INTL!B10) | C10: =IF(MOV_CC_INTL!C10="","",MOV_CC_INTL!C10) | D10: =IF(ISNUMBER(SEARCH("openai",LOWER(B10))),"AI Tools",IF(ISNUMBER(SEARCH("anthropic",LOWER(B10))),"AI Tools",IF(ISNUMBER(SEARCH("claude",LOWER(B10))),"AI Tools",IF(ISNUMBER(SEARCH("appbox",LOWER(B10))),"Digital Services",IF(ISNUMBER(SEARCH("apple",LOWER(B10))),"Digital Services",IF(ISNUMBER(SEARCH("playstation",LOWER(B10))),"Digital Services",IF(ISNUMBER(SEARCH("battle",LOWER(B10))),"Gaming","Other"))))))) -> Other | E10: =IF(C10="","",C10*CONFIG!B5)
A11: =IF(MOV_CC_INTL!A11="","",MOV_CC_INTL!A11) | B11: =IF(MOV_CC_INTL!B11="","",MOV_CC_INTL!B11) | C11: =IF(MOV_CC_INTL!C11="","",MOV_CC_INTL!C11) | D11: =IF(ISNUMBER(SEARCH("openai",LOWER(B11))),"AI Tools",IF(ISNUMBER(SEARCH("anthropic",LOWER(B11))),"AI Tools",IF(ISNUMBER(SEARCH("claude",LOWER(B11))),"AI Tools",IF(ISNUMBER(SEARCH("appbox",LOWER(B11))),"Digital Services",IF(ISNUMBER(SEARCH("apple",LOWER(B11))),"Digital Services",IF(ISNUMBER(SEARCH("playstation",LOWER(B11))),"Digital Services",IF(ISNUMBER(SEARCH("battle",LOWER(B11))),"Gaming","Other"))))))) -> Other | E11: =IF(C11="","",C11*CONFIG!B5)
A12: =IF(MOV_CC_INTL!A12="","",MOV_CC_INTL!A12) | B12: =IF(MOV_CC_INTL!B12="","",MOV_CC_INTL!B12) | C12: =IF(MOV_CC_INTL!C12="","",MOV_CC_INTL!C12) | D12: =IF(ISNUMBER(SEARCH("openai",LOWER(B12))),"AI Tools",IF(ISNUMBER(SEARCH("anthropic",LOWER(B12))),"AI Tools",IF(ISNUMBER(SEARCH("claude",LOWER(B12))),"AI Tools",IF(ISNUMBER(SEARCH("appbox",LOWER(B12))),"Digital Services",IF(ISNUMBER(SEARCH("apple",LOWER(B12))),"Digital Services",IF(ISNUMBER(SEARCH("playstation",LOWER(B12))),"Digital Services",IF(ISNUMBER(SEARCH("battle",LOWER(B12))),"Gaming","Other"))))))) -> Other | E12: =IF(C12="","",C12*CONFIG!B5)
A13: =IF(MOV_CC_INTL!A13="","",MOV_CC_INTL!A13) | B13: =IF(MOV_CC_INTL!B13="","",MOV_CC_INTL!B13) | C13: =IF(MOV_CC_INTL!C13="","",MOV_CC_INTL!C13) | D13: =IF(ISNUMBER(SEARCH("openai",LOWER(B13))),"AI Tools",IF(ISNUMBER(SEARCH("anthropic",LOWER(B13))),"AI Tools",IF(ISNUMBER(SEARCH("claude",LOWER(B13))),"AI Tools",IF(ISNUMBER(SEARCH("appbox",LOWER(B13))),"Digital Services",IF(ISNUMBER(SEARCH("apple",LOWER(B13))),"Digital Services",IF(ISNUMBER(SEARCH("playstation",LOWER(B13))),"Digital Services",IF(ISNUMBER(SEARCH("battle",LOWER(B13))),"Gaming","Other"))))))) -> Other | E13: =IF(C13="","",C13*CONFIG!B5)
A14: =IF(MOV_CC_INTL!A14="","",MOV_CC_INTL!A14) | B14: =IF(MOV_CC_INTL!B14="","",MOV_CC_INTL!B14) | C14: =IF(MOV_CC_INTL!C14="","",MOV_CC_INTL!C14) | D14: =IF(ISNUMBER(SEARCH("openai",LOWER(B14))),"AI Tools",IF(ISNUMBER(SEARCH("anthropic",LOWER(B14))),"AI Tools",IF(ISNUMBER(SEARCH("claude",LOWER(B14))),"AI Tools",IF(ISNUMBER(SEARCH("appbox",LOWER(B14))),"Digital Services",IF(ISNUMBER(SEARCH("apple",LOWER(B14))),"Digital Services",IF(ISNUMBER(SEARCH("playstation",LOWER(B14))),"Digital Services",IF(ISNUMBER(SEARCH("battle",LOWER(B14))),"Gaming","Other"))))))) -> Other | E14: =IF(C14="","",C14*CONFIG!B5)
A15: =IF(MOV_CC_INTL!A15="","",MOV_CC_INTL!A15) | B15: =IF(MOV_CC_INTL!B15="","",MOV_CC_INTL!B15) | C15: =IF(MOV_CC_INTL!C15="","",MOV_CC_INTL!C15) | D15: =IF(ISNUMBER(SEARCH("openai",LOWER(B15))),"AI Tools",IF(ISNUMBER(SEARCH("anthropic",LOWER(B15))),"AI Tools",IF(ISNUMBER(SEARCH("claude",LOWER(B15))),"AI Tools",IF(ISNUMBER(SEARCH("appbox",LOWER(B15))),"Digital Services",IF(ISNUMBER(SEARCH("apple",LOWER(B15))),"Digital Services",IF(ISNUMBER(SEARCH("playstation",LOWER(B15))),"Digital Services",IF(ISNUMBER(SEARCH("battle",LOWER(B15))),"Gaming","Other"))))))) -> Other | E15: =IF(C15="","",C15*CONFIG!B5)
A16: =IF(MOV_CC_INTL!A16="","",MOV_CC_INTL!A16) | B16: =IF(MOV_CC_INTL!B16="","",MOV_CC_INTL!B16) | C16: =IF(MOV_CC_INTL!C16="","",MOV_CC_INTL!C16) | D16: =IF(ISNUMBER(SEARCH("openai",LOWER(B16))),"AI Tools",IF(ISNUMBER(SEARCH("anthropic",LOWER(B16))),"AI Tools",IF(ISNUMBER(SEARCH("claude",LOWER(B16))),"AI Tools",IF(ISNUMBER(SEARCH("appbox",LOWER(B16))),"Digital Services",IF(ISNUMBER(SEARCH("apple",LOWER(B16))),"Digital Services",IF(ISNUMBER(SEARCH("playstation",LOWER(B16))),"Digital Services",IF(ISNUMBER(SEARCH("battle",LOWER(B16))),"Gaming","Other"))))))) -> Other | E16: =IF(C16="","",C16*CONFIG!B5)
A17: =IF(MOV_CC_INTL!A17="","",MOV_CC_INTL!A17) | B17: =IF(MOV_CC_INTL!B17="","",MOV_CC_INTL!B17) | C17: =IF(MOV_CC_INTL!C17="","",MOV_CC_INTL!C17) | D17: =IF(ISNUMBER(SEARCH("openai",LOWER(B17))),"AI Tools",IF(ISNUMBER(SEARCH("anthropic",LOWER(B17))),"AI Tools",IF(ISNUMBER(SEARCH("claude",LOWER(B17))),"AI Tools",IF(ISNUMBER(SEARCH("appbox",LOWER(B17))),"Digital Services",IF(ISNUMBER(SEARCH("apple",LOWER(B17))),"Digital Services",IF(ISNUMBER(SEARCH("playstation",LOWER(B17))),"Digital Services",IF(ISNUMBER(SEARCH("battle",LOWER(B17))),"Gaming","Other"))))))) -> Other | E17: =IF(C17="","",C17*CONFIG!B5)
A18: =IF(MOV_CC_INTL!A18="","",MOV_CC_INTL!A18) | B18: =IF(MOV_CC_INTL!B18="","",MOV_CC_INTL!B18) | C18: =IF(MOV_CC_INTL!C18="","",MOV_CC_INTL!C18) | D18: =IF(ISNUMBER(SEARCH("openai",LOWER(B18))),"AI Tools",IF(ISNUMBER(SEARCH("anthropic",LOWER(B18))),"AI Tools",IF(ISNUMBER(SEARCH("claude",LOWER(B18))),"AI Tools",IF(ISNUMBER(SEARCH("appbox",LOWER(B18))),"Digital Services",IF(ISNUMBER(SEARCH("apple",LOWER(B18))),"Digital Services",IF(ISNUMBER(SEARCH("playstation",LOWER(B18))),"Digital Services",IF(ISNUMBER(SEARCH("battle",LOWER(B18))),"Gaming","Other"))))))) -> Other | E18: =IF(C18="","",C18*CONFIG!B5)
A19: =IF(MOV_CC_INTL!A19="","",MOV_CC_INTL!A19) | B19: =IF(MOV_CC_INTL!B19="","",MOV_CC_INTL!B19) | C19: =IF(MOV_CC_INTL!C19="","",MOV_CC_INTL!C19) | D19: =IF(ISNUMBER(SEARCH("openai",LOWER(B19))),"AI Tools",IF(ISNUMBER(SEARCH("anthropic",LOWER(B19))),"AI Tools",IF(ISNUMBER(SEARCH("claude",LOWER(B19))),"AI Tools",IF(ISNUMBER(SEARCH("appbox",LOWER(B19))),"Digital Services",IF(ISNUMBER(SEARCH("apple",LOWER(B19))),"Digital Services",IF(ISNUMBER(SEARCH("playstation",LOWER(B19))),"Digital Services",IF(ISNUMBER(SEARCH("battle",LOWER(B19))),"Gaming","Other"))))))) -> Other | E19: =IF(C19="","",C19*CONFIG!B5)
